Workbook

Sheet Executive Dashboard
A1: B2B SaaS Revenue Pipeline Dashboard (12-Week RevOps Summary)
A4: TOTAL LEADS | C4: TOTAL CONVERSIONS | E4: NEW MRR ADDED | G4: FUNNEL CONVERSION
A5: =SUM('Weekly Metrics'!B6:B18) | C5: =SUM('Weekly Metrics'!D6:D18) | E5: =SUM('Weekly Metrics'!G6:G18) | G5: =E5/A5
A7: Key Performance Trends
A8: This tracker maps a simulated B2B SaaS funnel showing marketing drop-offs, onboarding speed, and MRR contribution.
A10: RevOps ETL Data Audit Report
A11: Metric | B11: Count
A12: Raw CRM Records Scanned | B12: 565
A13: Duplicate Leads Removed | B13: 15
A14: Missing Contact Emails Fixed | B14: 22
A15: Lead Source Casing Normalized | B15: 348
A16: Out-of-Order Dates Corrected | B16: 5
A17: MRR Valuation Anomalies Cleaned | B17: 3
A18: Final Cleaned CRM Records | B18: 550

Sheet Weekly Metrics
A1: Weekly Funnel & Revenue Tracking Table
A4: Week Start Date | B4: Leads Generated | C4: Trials Activated | D4: Conversions (Closed Won) | E4: Lead-to-Trial Rate | F4: Trial-to-Conversion Rate | G4: Weekly MRR Added | H4: Avg Velocity (Lead->Conv)
A5: 46082 | B5: =COUNTIFS('Cleaned Data'!$B$2:$B$600, ">=" & A5, 'Cleaned Data'!$B$2:$B$600, "<" & (A5 + 7)) | C5: =COUNTIFS('Cleaned Data'!$H$2:$H$600, ">=" & A5, 'Cleaned Data'!$H$2:$H$600, "<" & (A5 + 7), 'Cleaned Data'!$G$2:$G$600, "Yes") | D5: =COUNTIFS('Cleaned Data'!$J$2:$J$600, ">=" & A5, 'Cleaned Data'!$J$2:$J$600, "<" & (A5 + 7), 'Cleaned Data'!$I$2:$I$600, "Yes") | E5: =IF(B5=0, 0, C5/B5) | F5: =IF(C5=0, 0, D5/C5) | G5: =SUMIFS('Cleaned Data'!$K$2:$K$600, 'Cleaned Data'!$J$2:$J$600, ">=" & A5, 'Cleaned Data'!$J$2:$J$600, "<" & (A5 + 7)) | H5: =IFERROR(AVERAGEIFS('Cleaned Data'!$N$2:$N$600, 'Cleaned Data'!$J$2:$J$600, ">=" & A5, 'Cleaned Data'!$J$2:$J$600, "<" & (A5 + 7)), "-")
A6: 46089 | B6: =COUNTIFS('Cleaned Data'!$B$2:$B$600, ">=" & A6, 'Cleaned Data'!$B$2:$B$600, "<" & (A6 + 7)) | C6: =COUNTIFS('Cleaned Data'!$H$2:$H$600, ">=" & A6, 'Cleaned Data'!$H$2:$H$600, "<" & (A6 + 7), 'Cleaned Data'!$G$2:$G$600, "Yes") | D6: =COUNTIFS('Cleaned Data'!$J$2:$J$600, ">=" & A6, 'Cleaned Data'!$J$2:$J$600, "<" & (A6 + 7), 'Cleaned Data'!$I$2:$I$600, "Yes") | E6: =IF(B6=0, 0, C6/B6) | F6: =IF(C6=0, 0, D6/C6) | G6: =SUMIFS('Cleaned Data'!$K$2:$K$600, 'Cleaned Data'!$J$2:$J$600, ">=" & A6, 'Cleaned Data'!$J$2:$J$600, "<" & (A6 + 7)) | H6: =IFERROR(AVERAGEIFS('Cleaned Data'!$N$2:$N$600, 'Cleaned Data'!$J$2:$J$600, ">=" & A6, 'Cleaned Data'!$J$2:$J$600, "<" & (A6 + 7)), "-")
A7: 46096 | B7: =COUNTIFS('Cleaned Data'!$B$2:$B$600, ">=" & A7, 'Cleaned Data'!$B$2:$B$600, "<" & (A7 + 7)) | C7: =COUNTIFS('Cleaned Data'!$H$2:$H$600, ">=" & A7, 'Cleaned Data'!$H$2:$H$600, "<" & (A7 + 7), 'Cleaned Data'!$G$2:$G$600, "Yes") | D7: =COUNTIFS('Cleaned Data'!$J$2:$J$600, ">=" & A7, 'Cleaned Data'!$J$2:$J$600, "<" & (A7 + 7), 'Cleaned Data'!$I$2:$I$600, "Yes") | E7: =IF(B7=0, 0, C7/B7) | F7: =IF(C7=0, 0, D7/C7) | G7: =SUMIFS('Cleaned Data'!$K$2:$K$600, 'Cleaned Data'!$J$2:$J$600, ">=" & A7, 'Cleaned Data'!$J$2:$J$600, "<" & (A7 + 7)) | H7: =IFERROR(AVERAGEIFS('Cleaned Data'!$N$2:$N$600, 'Cleaned Data'!$J$2:$J$600, ">=" & A7, 'Cleaned Data'!$J$2:$J$600, "<" & (A7 + 7)), "-")
A8: 46103 | B8: =COUNTIFS('Cleaned Data'!$B$2:$B$600, ">=" & A8, 'Cleaned Data'!$B$2:$B$600, "<" & (A8 + 7)) | C8: =COUNTIFS('Cleaned Data'!$H$2:$H$600, ">=" & A8, 'Cleaned Data'!$H$2:$H$600, "<" & (A8 + 7), 'Cleaned Data'!$G$2:$G$600, "Yes") | D8: =COUNTIFS('Cleaned Data'!$J$2:$J$600, ">=" & A8, 'Cleaned Data'!$J$2:$J$600, "<" & (A8 + 7), 'Cleaned Data'!$I$2:$I$600, "Yes") | E8: =IF(B8=0, 0, C8/B8) | F8: =IF(C8=0, 0, D8/C8) | G8: =SUMIFS('Cleaned Data'!$K$2:$K$600, 'Cleaned Data'!$J$2:$J$600, ">=" & A8, 'Cleaned Data'!$J$2:$J$600, "<" & (A8 + 7)) | H8: =IFERROR(AVERAGEIFS('Cleaned Data'!$N$2:$N$600, 'Cleaned Data'!$J$2:$J$600, ">=" & A8, 'Cleaned Data'!$J$2:$J$600, "<" & (A8 + 7)), "-")
A9: 46110 | B9: =COUNTIFS('Cleaned Data'!$B$2:$B$600, ">=" & A9, 'Cleaned Data'!$B$2:$B$600, "<" & (A9 + 7)) | C9: =COUNTIFS('Cleaned Data'!$H$2:$H$600, ">=" & A9, 'Cleaned Data'!$H$2:$H$600, "<" & (A9 + 7), 'Cleaned Data'!$G$2:$G$600, "Yes") | D9: =COUNTIFS('Cleaned Data'!$J$2:$J$600, ">=" & A9, 'Cleaned Data'!$J$2:$J$600, "<" & (A9 + 7), 'Cleaned Data'!$I$2:$I$600, "Yes") | E9: =IF(B9=0, 0, C9/B9) | F9: =IF(C9=0, 0, D9/C9) | G9: =SUMIFS('Cleaned Data'!$K$2:$K$600, 'Cleaned Data'!$J$2:$J$600, ">=" & A9, 'Cleaned Data'!$J$2:$J$600, "<" & (A9 + 7)) | H9: =IFERROR(AVERAGEIFS('Cleaned Data'!$N$2:$N$600, 'Cleaned Data'!$J$2:$J$600, ">=" & A9, 'Cleaned Data'!$J$2:$J$600, "<" & (A9 + 7)), "-")
A10: 46117 | B10: =COUNTIFS('Cleaned Data'!$B$2:$B$600, ">=" & A10, 'Cleaned Data'!$B$2:$B$600, "<" & (A10 + 7)) | C10: =COUNTIFS('Cleaned Data'!$H$2:$H$600, ">=" & A10, 'Cleaned Data'!$H$2:$H$600, "<" & (A10 + 7), 'Cleaned Data'!$G$2:$G$600, "Yes") | D10: =COUNTIFS('Cleaned Data'!$J$2:$J$600, ">=" & A10, 'Cleaned Data'!$J$2:$J$600, "<" & (A10 + 7), 'Cleaned Data'!$I$2:$I$600, "Yes") | E10: =IF(B10=0, 0, C10/B10) | F10: =IF(C10=0, 0, D10/C10) | G10: =SUMIFS('Cleaned Data'!$K$2:$K$600, 'Cleaned Data'!$J$2:$J$600, ">=" & A10, 'Cleaned Data'!$J$2:$J$600, "<" & (A10 + 7)) | H10: =IFERROR(AVERAGEIFS('Cleaned Data'!$N$2:$N$600, 'Cleaned Data'!$J$2:$J$600, ">=" & A10, 'Cleaned Data'!$J$2:$J$600, "<" & (A10 + 7)), "-")
A11: 46124 | B11: =COUNTIFS('Cleaned Data'!$B$2:$B$600, ">=" & A11, 'Cleaned Data'!$B$2:$B$600, "<" & (A11 + 7)) | C11: =COUNTIFS('Cleaned Data'!$H$2:$H$600, ">=" & A11, 'Cleaned Data'!$H$2:$H$600, "<" & (A11 + 7), 'Cleaned Data'!$G$2:$G$600, "Yes") | D11: =COUNTIFS('Cleaned Data'!$J$2:$J$600, ">=" & A11, 'Cleaned Data'!$J$2:$J$600, "<" & (A11 + 7), 'Cleaned Data'!$I$2:$I$600, "Yes") | E11: =IF(B11=0, 0, C11/B11) | F11: =IF(C11=0, 0, D11/C11) | G11: =SUMIFS('Cleaned Data'!$K$2:$K$600, 'Cleaned Data'!$J$2:$J$600, ">=" & A11, 'Cleaned Data'!$J$2:$J$600, "<" & (A11 + 7)) | H11: =IFERROR(AVERAGEIFS('Cleaned Data'!$N$2:$N$600, 'Cleaned Data'!$J$2:$J$600, ">=" & A11, 'Cleaned Data'!$J$2:$J$600, "<" & (A11 + 7)), "-")
A12: 46131 | B12: =COUNTIFS('Cleaned Data'!$B$2:$B$600, ">=" & A12, 'Cleaned Data'!$B$2:$B$600, "<" & (A12 + 7)) | C12: =COUNTIFS('Cleaned Data'!$H$2:$H$600, ">=" & A12, 'Cleaned Data'!$H$2:$H$600, "<" & (A12 + 7), 'Cleaned Data'!$G$2:$G$600, "Yes") | D12: =COUNTIFS('Cleaned Data'!$J$2:$J$600, ">=" & A12, 'Cleaned Data'!$J$2:$J$600, "<" & (A12 + 7), 'Cleaned Data'!$I$2:$I$600, "Yes") | E12: =IF(B12=0, 0, C12/B12) | F12: =IF(C12=0, 0, D12/C12) | G12: =SUMIFS('Cleaned Data'!$K$2:$K$600, 'Cleaned Data'!$J$2:$J$600, ">=" & A12, 'Cleaned Data'!$J$2:$J$600, "<" & (A12 + 7)) | H12: =IFERROR(AVERAGEIFS('Cleaned Data'!$N$2:$N$600, 'Cleaned Data'!$J$2:$J$600, ">=" & A12, 'Cleaned Data'!$J$2:$J$600, "<" & (A12 + 7)), "-")
A13: 46138 | B13: =COUNTIFS('Cleaned Data'!$B$2:$B$600, ">=" & A13, 'Cleaned Data'!$B$2:$B$600, "<" & (A13 + 7)) | C13: =COUNTIFS('Cleaned Data'!$H$2:$H$600, ">=" & A13, 'Cleaned Data'!$H$2:$H$600, "<" & (A13 + 7), 'Cleaned Data'!$G$2:$G$600, "Yes") | D13: =COUNTIFS('Cleaned Data'!$J$2:$J$600, ">=" & A13, 'Cleaned Data'!$J$2:$J$600, "<" & (A13 + 7), 'Cleaned Data'!$I$2:$I$600, "Yes") | E13: =IF(B13=0, 0, C13/B13) | F13: =IF(C13=0, 0, D13/C13) | G13: =SUMIFS('Cleaned Data'!$K$2:$K$600, 'Cleaned Data'!$J$2:$J$600, ">=" & A13, 'Cleaned Data'!$J$2:$J$600, "<" & (A13 + 7)) | H13: =IFERROR(AVERAGEIFS('Cleaned Data'!$N$2:$N$600, 'Cleaned Data'!$J$2:$J$600, ">=" & A13, 'Cleaned Data'!$J$2:$J$600, "<" & (A13 + 7)), "-")
A14: 46145 | B14: =COUNTIFS('Cleaned Data'!$B$2:$B$600, ">=" & A14, 'Cleaned Data'!$B$2:$B$600, "<" & (A14 + 7)) | C14: =COUNTIFS('Cleaned Data'!$H$2:$H$600, ">=" & A14, 'Cleaned Data'!$H$2:$H$600, "<" & (A14 + 7), 'Cleaned Data'!$G$2:$G$600, "Yes") | D14: =COUNTIFS('Cleaned Data'!$J$2:$J$600, ">=" & A14, 'Cleaned Data'!$J$2:$J$600, "<" & (A14 + 7), 'Cleaned Data'!$I$2:$I$600, "Yes") | E14: =IF(B14=0, 0, C14/B14) | F14: =IF(C14=0, 0, D14/C14) | G14: =SUMIFS('Cleaned Data'!$K$2:$K$600, 'Cleaned Data'!$J$2:$J$600, ">=" & A14, 'Cleaned Data'!$J$2:$J$600, "<" & (A14 + 7)) | H14: =IFERROR(AVERAGEIFS('Cleaned Data'!$N$2:$N$600, 'Cleaned Data'!$J$2:$J$600, ">=" & A14, 'Cleaned Data'!$J$2:$J$600, "<" & (A14 + 7)), "-")
A15: 46152 | B15: =COUNTIFS('Cleaned Data'!$B$2:$B$600, ">=" & A15, 'Cleaned Data'!$B$2:$B$600, "<" & (A15 + 7)) | C15: =COUNTIFS('Cleaned Data'!$H$2:$H$600, ">=" & A15, 'Cleaned Data'!$H$2:$H$600, "<" & (A15 + 7), 'Cleaned Data'!$G$2:$G$600, "Yes") | D15: =COUNTIFS('Cleaned Data'!$J$2:$J$600, ">=" & A15, 'Cleaned Data'!$J$2:$J$600, "<" & (A15 + 7), 'Cleaned Data'!$I$2:$I$600, "Yes") | E15: =IF(B15=0, 0, C15/B15) | F15: =IF(C15=0, 0, D15/C15) | G15: =SUMIFS('Cleaned Data'!$K$2:$K$600, 'Cleaned Data'!$J$2:$J$600, ">=" & A15, 'Cleaned Data'!$J$2:$J$600, "<" & (A15 + 7)) | H15: =IFERROR(AVERAGEIFS('Cleaned Data'!$N$2:$N$600, 'Cleaned Data'!$J$2:$J$600, ">=" & A15, 'Cleaned Data'!$J$2:$J$600, "<" & (A15 + 7)), "-")
A16: 46159 | B16: =COUNTIFS('Cleaned Data'!$B$2:$B$600, ">=" & A16, 'Cleaned Data'!$B$2:$B$600, "<" & (A16 + 7)) | C16: =COUNTIFS('Cleaned Data'!$H$2:$H$600, ">=" & A16, 'Cleaned Data'!$H$2:$H$600, "<" & (A16 + 7), 'Cleaned Data'!$G$2:$G$600, "Yes") | D16: =COUNTIFS('Cleaned Data'!$J$2:$J$600, ">=" & A16, 'Cleaned Data'!$J$2:$J$600, "<" & (A16 + 7), 'Cleaned Data'!$I$2:$I$600, "Yes") | E16: =IF(B16=0, 0, C16/B16) | F16: =IF(C16=0, 0, D16/C16) | G16: =SUMIFS('Cleaned Data'!$K$2:$K$600, 'Cleaned Data'!$J$2:$J$600, ">=" & A16, 'Cleaned Data'!$J$2:$J$600, "<" & (A16 + 7)) | H16: =IFERROR(AVERAGEIFS('Cleaned Data'!$N$2:$N$600, 'Cleaned Data'!$J$2:$J$600, ">=" & A16, 'Cleaned Data'!$J$2:$J$600, "<" & (A16 + 7)), "-")
A17: 46166 | B17: =COUNTIFS('Cleaned Data'!$B$2:$B$600, ">=" & A17, 'Cleaned Data'!$B$2:$B$600, "<" & (A17 + 7)) | C17: =COUNTIFS('Cleaned Data'!$H$2:$H$600, ">=" & A17, 'Cleaned Data'!$H$2:$H$600, "<" & (A17 + 7), 'Cleaned Data'!$G$2:$G$600, "Yes") | D17: =COUNTIFS('Cleaned Data'!$J$2:$J$600, ">=" & A17, 'Cleaned Data'!$J$2:$J$600, "<" & (A17 + 7), 'Cleaned Data'!$I$2:$I$600, "Yes") | E17: =IF(B17=0, 0, C17/B17) | F17: =IF(C17=0, 0, D17/C17) | G17: =SUMIFS('Cleaned Data'!$K$2:$K$600, 'Cleaned Data'!$J$2:$J$600, ">=" & A17, 'Cleaned Data'!$J$2:$J$600, "<" & (A17 + 7)) | H17: =IFERROR(AVERAGEIFS('Cleaned Data'!$N$2:$N$600, 'Cleaned Data'!$J$2:$J$600, ">=" & A17, 'Cleaned Data'!$J$2:$J$600, "<" & (A17 + 7)), "-")
A18: Total | B18: =SUM(B5:B17) | C18: =SUM(C5:C17) | D18: =SUM(D5:D17) | E18: =C18/B18 | F18: =D18/C18 | G18: =SUM(G5:G17) | H18: =AVERAGE('Cleaned Data'!$N$2:$N$600)

Sheet Cleaned Data
A1: Lead_ID | B1: Lead_Date | C1: Company_Name | D1: Contact_Email | E1: Lead_Source | F1: Segment | G1: Trial_Activated | H1: Trial_Date | I1: Converted | J1: Conversion_Date | K1: MRR | L1: Lead_to_Trial_Days | M1: Trial_to_Conversion_Days | N1: Total_Deal_Velocity
A2: LD-1452 | B2: 46116 | C2: Zenith Solutions | D2: info@zenithsolutions.com | E2: Cold Outreach | F2: SMB | G2: Yes | H2: 46118 | I2: Yes | J2: 46127 | K2: 283 | L2: =IF(G2="Yes", H2-B2, "") | M2: =IF(I2="Yes", J2-H2, "") | N2: =IF(I2="Yes", J2-B2, "")
A3: LD-1131 | B3: 46154 | C3: Alpha Co | D3: info@alphaco.com | E3: Google | F3: Mid-Market | G3: Yes | H3: 46162 | I3: No | L3: =IF(G3="Yes", H3-B3, "") | M3: =IF(I3="Yes", J3-H3, "") | N3: =IF(I3="Yes", J3-B3, "")
A4: LD-1478 | B4: 46159 | C4: Stellar Global | D4: info@stellarglobal.com | E4: Google | F4: Mid-Market | G4: Yes | H4: 46163 | I4: No | L4: =IF(G4="Yes", H4-B4, "") | M4: =IF(I4="Yes", J4-H4, "") | N4: =IF(I4="Yes", J4-B4, "")
A5: LD-1177 | B5: 46099 | C5: Omega Co | D5: info@omegaco.com | E5: Cold Outreach | F5: SMB | G5: Yes | H5: 46104 | I5: No | L5: =IF(G5="Yes", H5-B5, "") | M5: =IF(I5="Yes", J5-H5, "") | N5: =IF(I5="Yes", J5-B5, "")
A6: LD-1504 | B6: 46140 | C6: Core Group | D6: info@coregroup.com | E6: Google | F6: Enterprise | G6: Yes | H6: 46146 | I6: Yes | J6: 46163 | K6: 5000 | L6: =IF(G6="Yes", H6-B6, "") | M6: =IF(I6="Yes", J6-H6, "") | N6: =IF(I6="Yes", J6-B6, "")
A7: LD-1270 | B7: 46100 | C7: Shift Inc | D7: info@shiftinc.com | E7: LinkedIn | F7: Enterprise | G7: Yes | H7: 46103 | I7: No | L7: =IF(G7="Yes", H7-B7, "") | M7: =IF(I7="Yes", J7-H7, "") | N7: =IF(I7="Yes", J7-B7, "")
A8: LD-1540 | B8: 46120 | C8: Flux Corp | D8: info@fluxcorp.com | E8: Cold Outreach | F8: Mid-Market | G8: No | I8: No | L8: =IF(G8="Yes", H8-B8, "") | M8: =IF(I8="Yes", J8-H8, "") | N8: =IF(I8="Yes", J8-B8, "")
A9: LD-1314 | B9: 46085 | C9: Summit LLC | D9: info@summitllc.com | E9: LinkedIn | F9: SMB | G9: Yes | H9: 46094 | I9: No | L9: =IF(G9="Yes", H9-B9, "") | M9: =IF(I9="Yes", J9-H9, "") | N9: =IF(I9="Yes", J9-B9, "")
A10: LD-1150 | B10: 46092 | C10: Flux Corp | D10: info@fluxcorp.com | E10: Organic / Direct | F10: Enterprise | G10: Yes | H10: 46099 | I10: No | L10: =IF(G10="Yes", H10-B10, "") | M10: =IF(I10="Yes", J10-H10, "") | N10: =IF(I10="Yes", J10-B10, "")
A11: LD-1273 | B11: 46085 | C11: Stellar Solutions | D11: info@stellarsolutions.com | E11: Organic / Direct | F11: Mid-Market | G11: Yes | H11: 46086 | I11: No | L11: =IF(G11="Yes", H11-B11, "") | M11: =IF(I11="Yes", J11-H11, "") | N11: =IF(I11="Yes", J11-B11, "")
A12: LD-1126 | B12: 46146 | C12: Flux Corp | D12: info@fluxcorp.com | E12: Referral | F12: SMB | G12: Yes | H12: 46148 | I12: No | L12: =IF(G12="Yes", H12-B12, "") | M12: =IF(I12="Yes", J12-H12, "") | N12: =IF(I12="Yes", J12-B12, "")
A13: LD-1040 | B13: 46082 | C13: Pulse Solutions | D13: info@pulsesolutions.com | E13: Webinar | F13: Mid-Market | G13: Yes | H13: 46084 | I13: No | L13: =IF(G13="Yes", H13-B13, "") | M13: =IF(I13="Yes", J13-H13, "") | N13: =IF(I13="Yes", J13-B13, "")
A14: LD-1404 | B14: 46163 | C14: Beacon Global | D14: info@beaconglobal.com | E14: Referral | F14: Mid-Market | G14: Yes | H14: 46165 | I14: No | L14: =IF(G14="Yes", H14-B14, "") | M14: =IF(I14="Yes", J14-H14, "") | N14: =IF(I14="Yes", J14-B14, "")
A15: LD-1264 | B15: 46145 | C15: Stellar Co (Duplicate Entry) | D15: info@stellarco.com | E15: Referral | F15: Mid-Market | G15: No | I15: No | L15: =IF(G15="Yes", H15-B15, "") | M15: =IF(I15="Yes", J15-H15, "") | N15: =IF(I15="Yes", J15-B15, "")
A16: LD-1434 | B16: 46105 | C16: Synergy Technologies | D16: info@synergytechnologies.com | E16: LinkedIn | F16: SMB | G16: Yes | H16: 46109 | I16: No | L16: =IF(G16="Yes", H16-B16, "") | M16: =IF(I16="Yes", J16-H16, "") | N16: =IF(I16="Yes", J16-B16, "")
A17: LD-1519 | B17: 46164 | C17: Sovereign Partners | D17: info@sovereignpartners.com | E17: LinkedIn | F17: Mid-Market | G17: No | I17: No | L17: =IF(G17="Yes", H17-B17, "") | M17: =IF(I17="Yes", J17-H17, "") | N17: =IF(I17="Yes", J17-B17, "")
A18: LD-1258 | B18: 46086 | C18: Flux Corp | D18: info@fluxcorp.com | E18: Organic / Direct | F18: SMB | G18: Yes | H18: 46096 | I18: No | L18: =IF(G18="Yes", H18-B18, "") | M18: =IF(I18="Yes", J18-H18, "") | N18: =IF(I18="Yes", J18-B18, "")
A19: LD-1449 | B19: 46144 | C19: Acme LLC | D19: info@acmellc.com | E19: Organic / Direct | F19: SMB | G19: Yes | H19: 46148 | I19: No | L19: =IF(G19="Yes", H19-B19, "") | M19: =IF(I19="Yes", J19-H19, "") | N19: =IF(I19="Yes", J19-B19, "")
A20: LD-1205 | B20: 46084 | C20: Acme Solutions | D20: info@acmesolutions.com | E20: LinkedIn | F20: Enterprise | G20: Yes | H20: 46085 | I20: No | L20: =IF(G20="Yes", H20-B20, "") | M20: =IF(I20="Yes", J20-H20, "") | N20: =IF(I20="Yes", J20-B20, "")
A21: LD-1147 | B21: 46084 | C21: Sovereign Global | D21: info@sovereignglobal.com | E21: Referral | F21: SMB | G21: No | I21: No | L21: =IF(G21="Yes", H21-B21, "") | M21: =IF(I21="Yes", J21-H21, "") | N21: =IF(I21="Yes", J21-B21, "")
A22: LD-1049 | B22: 46117 | C22: Cloud Partners | D22: info@cloudpartners.com | E22: Google | F22: Enterprise | G22: Yes | H22: 46122 | I22: No | L22: =IF(G22="Yes", H22-B22, "") | M22: =IF(I22="Yes", J22-H22, "") | N22: =IF(I22="Yes", J22-B22, "")
A23: LD-1268 | B23: 46138 | C23: Core Corp (Duplicate Entry) | D23: info@corecorp.com | E23: Google | F23: Mid-Market | G23: Yes | H23: 46145 | I23: Yes | J23: 46153 | K23: 605 | L23: =IF(G23="Yes", H23-B23, "") | M23: =IF(I23="Yes", J23-H23, "") | N23: =IF(I23="Yes", J23-B23, "")
A24: LD-1080 | B24: 46145 | C24: Omega Global | D24: info@omegaglobal.com | E24: LinkedIn | F24: Mid-Market | G24: Yes | H24: 46152 | I24: No | L24: =IF(G24="Yes", H24-B24, "") | M24: =IF(I24="Yes", J24-H24, "") | N24: =IF(I24="Yes", J24-B24, "")
A25: LD-1364 | B25: 46153 | C25: Nova Technologies | D25: info@novatechnologies.com | E25: Webinar | F25: Enterprise | G25: Yes | H25: 46159 | I25: No | L25: =IF(G25="Yes", H25-B25, "") | M25: =IF(I25="Yes", J25-H25, "") | N25: =IF(I25="Yes", J25-B25, "")
A26: LD-1418 | B26: 46121 | C26: Omega Group | D26: info@omegagroup.com | E26: Organic / Direct | F26: SMB | G26: Yes | H26: 46124 | I26: Yes | J26: 46141 | K26: 186 | L26: =IF(G26="Yes", H26-B26, "") | M26: =IF(I26="Yes", J26-H26, "") | N26: =IF(I26="Yes", J26-B26, "")
A27: LD-1007 | B27: 46164 | C27: Summit Global | D27: info@summitglobal.com | E27: Referral | F27: Mid-Market | G27: No | I27: No | L27: =IF(G27="Yes", H27-B27, "") | M27: =IF(I27="Yes", J27-H27, "") | N27: =IF(I27="Yes", J27-B27, "")
A28: LD-1298 | B28: 46132 | C28: Omega LLC | D28: info@omegallc.com | E28: Google | F28: Mid-Market | G28: Yes | H28: 46135 | I28: Yes | J28: 46147 | K28: 1162 | L28: =IF(G28="Yes", H28-B28, "") | M28: =IF(I28="Yes", J28-H28, "") | N28: =IF(I28="Yes", J28-B28, "")
A29: LD-1467 | B29: 46159 | C29: Acme Solutions | D29: info@acmesolutions.com | E29: Google | F29: Mid-Market | G29: No | I29: No | L29: =IF(G29="Yes", H29-B29, "") | M29: =IF(I29="Yes", J29-H29, "") | N29: =IF(I29="Yes", J29-B29, "")
A30: LD-1135 | B30: 46125 | C30: Summit Inc | D30: info@summitinc.com | E30: Referral | F30: Enterprise | G30: Yes | H30: 46128 | I30: No | L30: =IF(G30="Yes", H30-B30, "") | M30: =IF(I30="Yes", J30-H30, "") | N30: =IF(I30="Yes", J30-B30, "")
A31: LD-1220 | B31: 46165 | C31: Zenith Partners | D31: info@zenithpartners.com | E31: LinkedIn | F31: SMB | G31: Yes | H31: 46174 | I31: No | L31: =IF(G31="Yes", H31-B31, "") | M31: =IF(I31="Yes", J31-H31, "") | N31: =IF(I31="Yes", J31-B31, "")
A32: LD-1511 | B32: 46093 | C32: Core Co | D32: info@coreco.com | E32: Organic / Direct | F32: Mid-Market | G32: No | I32: No | L32: =IF(G32="Yes", H32-B32, "") | M32: =IF(I32="Yes", J32-H32, "") | N32: =IF(I32="Yes", J32-B32, "")
A33: LD-1127 | B33: 46155 | C33: Omega LLC | D33: info@omegallc.com | E33: LinkedIn | F33: SMB | G33: No | I33: No | L33: =IF(G33="Yes", H33-B33, "") | M33: =IF(I33="Yes", J33-H33, "") | N33: =IF(I33="Yes", J33-B33, "")
A34: LD-1066 | B34: 46139 | C34: Nova Technologies | D34: info@novatechnologies.com | E34: LinkedIn | F34: Enterprise | G34: Yes | H34: 46147 | I34: No | L34: =IF(G34="Yes", H34-B34, "") | M34: =IF(I34="Yes", J34-H34, "") | N34: =IF(I34="Yes", J34-B34, "")
A35: LD-1145 | B35: 46093 | C35: Alpha Co | D35: info@alphaco.com | E35: Referral | F35: Enterprise | G35: Yes | H35: 46100 | I35: Yes | J35: 46115 | K35: 5746 | L35: =IF(G35="Yes", H35-B35, "") | M35: =IF(I35="Yes", J35-H35, "") | N35: =IF(I35="Yes", J35-B35, "")
A36: LD-1003 | B36: 46139 | C36: Acme Group | D36: info@acmegroup.com | E36: Google | F36: SMB | G36: No | I36: No | L36: =IF(G36="Yes", H36-B36, "") | M36: =IF(I36="Yes", J36-H36, "") | N36: =IF(I36="Yes", J36-B36, "")
A37: LD-1034 | B37: 46100 | C37: Apex Technologies | D37: info@apextechnologies.com | E37: Google | F37: Mid-Market | G37: Yes | H37: 46104 | I37: No | L37: =IF(G37="Yes", H37-B37, "") | M37: =IF(I37="Yes", J37-H37, "") | N37: =IF(I37="Yes", J37-B37, "")
A38: LD-1319 | B38: 46151 | C38: Shift Solutions | D38: info@shiftsolutions.com | E38: Cold Outreach | F38: Mid-Market | G38: No | I38: No | L38: =IF(G38="Yes", H38-B38, "") | M38: =IF(I38="Yes", J38-H38, "") | N38: =IF(I38="Yes", J38-B38, "")
A39: LD-1223 | B39: 46117 | C39: Stellar Inc | D39: info@stellarinc.com | E39: Referral | F39: SMB | G39: Yes | H39: 46119 | I39: No | L39: =IF(G39="Yes", H39-B39, "") | M39: =IF(I39="Yes", J39-H39, "") | N39: =IF(I39="Yes", J39-B39, "")
A40: LD-1115 | B40: 46096 | C40: Quantum LLC | D40: info@quantumllc.com | E40: LinkedIn | F40: Mid-Market | G40: Yes | H40: 46098 | I40: No | L40: =IF(G40="Yes", H40-B40, "") | M40: =IF(I40="Yes", J40-H40, "") | N40: =IF(I40="Yes", J40-B40, "")
...
